<?xml version="1.0" ?>
<robot name="robot">
  <link name="root_link"/>
  <joint name="arm_left_joint" type="revolute">
    <origin xyz="0.0 0.0 0.0" rpy="0 0 0"/>
    <child link="arm_left_link"/>
    <parent link="base_link"/>
  </joint>
  <link name="arm_left_link">
    <collision>
      <geometry>
        <box size="1.2 0.1 0.1"/>
      </geometry>
      <origin xyz="0.0 0.0 0.0" rpy="0.0 0.0 0.0"/>
    </collision>
    <visual>
      <geometry>
        <box size="1.2 0.1 0.1"/>
      </geometry>
      <origin xyz="0.0 0.0 0.0" rpy="0.0 0.0 0.0"/>
    </visual>
  </link>
  <joint name="arm_right_joint" type="revolute">
    <origin xyz="0.0 0.0 0.0" rpy="0 0 0"/>
    <child link="arm_right_link"/>
    <parent link="base_link"/>
  </joint>
  <link name="arm_right_link">
    <collision>
      <geometry>
        <box size="1.0 0.1 0.1"/>
      </geometry>
      <origin xyz="0.0 0.0 0.0" rpy="0.0 0.0 0.0"/>
    </collision>
    <visual>
      <geometry>
        <box size="1.0 0.1 0.1"/>
      </geometry>
      <origin xyz="0.0 0.0 0.0" rpy="0.0 0.0 0.0"/>
    </visual>
  </link>
</robot>
