<?xml version="1.0" ?>
<robot name="drone">
  <link name="root_link"/>
  <joint name="base_joint" type="fixed">
    <origin xyz="0.0 0.0 0.0" rpy="0 0 0"/>
    <child link="base_link"/>
    <parent link="root_link"/>
  </joint>
  <link name="base_link">
    <visual>
      <geometry>
        <cylinder radius="0.25" length="0.08"/>
      </geometry>
      <origin xyz="0.0 0.0 0.04" rpy="0.0 0.0 0.0"/>
    </visual>
    <inertial>
      <mass value="10"/>
      <origin xyz="0.0 0.0 0.04" rpy="0.0 0.0 0.0"/>
      <inertia ixx="0.16158333333333333" ixy="0" ixz="0" iyy="0.16158333333333333" iyz="0" izz="0.3125"/>
    </inertial>
    <collision>
      <geometry>
        <cylinder radius="0.25" length="0.08"/>
      </geometry>
      <origin xyz="0.0 0.0 0.04" rpy="0.0 0.0 0.0"/>
    </collision>
  </link>
  <joint name="arm_0_joint" type="revolute">
    <origin xyz="0.25 0.0 0.04" rpy="0 0 0.0"/>
    <child link="arm_0_link"/>
    <parent link="base_link"/>
    <axis xyz="0 1 0">
    </axis>
    <limit effort="1" lower="-1.5707963267948966" upper="1.5707963267948966" velocity="10">
    </limit>
    <dynamics damping="10" friction="0">
    </dynamics>
  </joint>
  <link name="arm_0_link">
    <collision>
      <geometry>
        <cylinder radius="0.015" length="0.8"/>
      </geometry>
      <origin xyz="0.3939231012048832 0.0 0.06945927106677217" rpy="0.0 1.3962634015954636 0.0"/>
    </collision>
    <visual>
      <geometry>
        <cylinder radius="0.015" length="0.8"/>
      </geometry>
      <origin xyz="0.3939231012048832 0.0 0.06945927106677217" rpy="0.0 1.3962634015954636 0.0"/>
    </visual>
    <inertial>
      <mass value="0.05"/>
      <origin xyz="0.3939231012048832 0.0 0.06945927106677217" rpy="0.0 1.3962634015954636 0.0"/>
      <inertia ixx="0.0026694791666666672" ixy="0" ixz="0" iyy="0.0026694791666666672" iyz="0" izz="5.625e-06"/>
    </inertial>
  </link>
  <gazebo reference="arm_0_joint">
    <springStiffness>500</springStiffness>
    <springReference>0</springReference>
  </gazebo>
  <joint name="arm_1_joint" type="revolute">
    <origin xyz="0.12500000000000003 0.21650635094610965 0.04" rpy="0 0 1.0471975511965976"/>
    <child link="arm_1_link"/>
    <parent link="base_link"/>
    <axis xyz="0 1 0">
    </axis>
    <limit effort="1" lower="-1.5707963267948966" upper="1.5707963267948966" velocity="10">
    </limit>
    <dynamics damping="10" friction="0">
    </dynamics>
  </joint>
  <link name="arm_1_link">
    <collision>
      <geometry>
        <cylinder radius="0.015" length="0.8"/>
      </geometry>
      <origin xyz="0.3939231012048832 0.0 0.06945927106677217" rpy="0.0 1.3962634015954636 0.0"/>
    </collision>
    <visual>
      <geometry>
        <cylinder radius="0.015" length="0.8"/>
      </geometry>
      <origin xyz="0.3939231012048832 0.0 0.06945927106677217" rpy="0.0 1.3962634015954636 0.0"/>
    </visual>
    <inertial>
      <mass value="0.05"/>
      <origin xyz="0.3939231012048832 0.0 0.06945927106677217" rpy="0.0 1.3962634015954636 0.0"/>
      <inertia ixx="0.0026694791666666672" ixy="0" ixz="0" iyy="0.0026694791666666672" iyz="0" izz="5.625e-06"/>
    </inertial>
  </link>
  <gazebo reference="arm_1_joint">
    <springStiffness>500</springStiffness>
    <springReference>0</springReference>
  </gazebo>
  <joint name="arm_2_joint" type="revolute">
    <origin xyz="-0.12499999999999994 0.21650635094610968 0.04" rpy="0 0 2.0943951023931953"/>
    <child link="arm_2_link"/>
    <parent link="base_link"/>
    <axis xyz="0 1 0">
    </axis>
    <limit effort="1" lower="-1.5707963267948966" upper="1.5707963267948966" velocity="10">
    </limit>
    <dynamics damping="10" friction="0">
    </dynamics>
  </joint>
  <link name="arm_2_link">
    <collision>
      <geometry>
        <cylinder radius="0.015" length="0.8"/>
      </geometry>
      <origin xyz="0.3939231012048832 0.0 0.06945927106677217" rpy="0.0 1.3962634015954636 0.0"/>
    </collision>
    <visual>
      <geometry>
        <cylinder radius="0.015" length="0.8"/>
      </geometry>
      <origin xyz="0.3939231012048832 0.0 0.06945927106677217" rpy="0.0 1.3962634015954636 0.0"/>
    </visual>
    <inertial>
      <mass value="0.05"/>
      <origin xyz="0.3939231012048832 0.0 0.06945927106677217" rpy="0.0 1.3962634015954636 0.0"/>
      <inertia ixx="0.0026694791666666672" ixy="0" ixz="0" iyy="0.0026694791666666672" iyz="0" izz="5.625e-06"/>
    </inertial>
  </link>
  <gazebo reference="arm_2_joint">
    <springStiffness>500</springStiffness>
    <springReference>0</springReference>
  </gazebo>
  <joint name="arm_3_joint" type="revolute">
    <origin xyz="-0.25 3.061616997868383e-17 0.04" rpy="0 0 3.141592653589793"/>
    <child link="arm_3_link"/>
    <parent link="base_link"/>
    <axis xyz="0 1 0">
    </axis>
    <limit effort="1" lower="-1.5707963267948966" upper="1.5707963267948966" velocity="10">
    </limit>
    <dynamics damping="10" friction="0">
    </dynamics>
  </joint>
  <link name="arm_3_link">
    <collision>
      <geometry>
        <cylinder radius="0.015" length="0.8"/>
      </geometry>
      <origin xyz="0.3939231012048832 0.0 0.06945927106677217" rpy="0.0 1.3962634015954636 0.0"/>
    </collision>
    <visual>
      <geometry>
        <cylinder radius="0.015" length="0.8"/>
      </geometry>
      <origin xyz="0.3939231012048832 0.0 0.06945927106677217" rpy="0.0 1.3962634015954636 0.0"/>
    </visual>
    <inertial>
      <mass value="0.05"/>
      <origin xyz="0.3939231012048832 0.0 0.06945927106677217" rpy="0.0 1.3962634015954636 0.0"/>
      <inertia ixx="0.0026694791666666672" ixy="0" ixz="0" iyy="0.0026694791666666672" iyz="0" izz="5.625e-06"/>
    </inertial>
  </link>
  <gazebo reference="arm_3_joint">
    <springStiffness>500</springStiffness>
    <springReference>0</springReference>
  </gazebo>
  <joint name="arm_4_joint" type="revolute">
    <origin xyz="-0.1250000000000001 -0.2165063509461096 0.04" rpy="0 0 4.1887902047863905"/>
    <child link="arm_4_link"/>
    <parent link="base_link"/>
    <axis xyz="0 1 0">
    </axis>
    <limit effort="1" lower="-1.5707963267948966" upper="1.5707963267948966" velocity="10">
    </limit>
    <dynamics damping="10" friction="0">
    </dynamics>
  </joint>
  <link name="arm_4_link">
    <collision>
      <geometry>
        <cylinder radius="0.015" length="0.8"/>
      </geometry>
      <origin xyz="0.3939231012048832 0.0 0.06945927106677217" rpy="0.0 1.3962634015954636 0.0"/>
    </collision>
    <visual>
      <geometry>
        <cylinder radius="0.015" length="0.8"/>
      </geometry>
      <origin xyz="0.3939231012048832 0.0 0.06945927106677217" rpy="0.0 1.3962634015954636 0.0"/>
    </visual>
    <inertial>
      <mass value="0.05"/>
      <origin xyz="0.3939231012048832 0.0 0.06945927106677217" rpy="0.0 1.3962634015954636 0.0"/>
      <inertia ixx="0.0026694791666666672" ixy="0" ixz="0" iyy="0.0026694791666666672" iyz="0" izz="5.625e-06"/>
    </inertial>
  </link>
  <gazebo reference="arm_4_joint">
    <springStiffness>500</springStiffness>
    <springReference>0</springReference>
  </gazebo>
  <joint name="arm_5_joint" type="revolute">
    <origin xyz="0.12500000000000003 -0.21650635094610965 0.04" rpy="0 0 5.235987755982989"/>
    <child link="arm_5_link"/>
    <parent link="base_link"/>
    <axis xyz="0 1 0">
    </axis>
    <limit effort="1" lower="-1.5707963267948966" upper="1.5707963267948966" velocity="10">
    </limit>
    <dynamics damping="10" friction="0">
    </dynamics>
  </joint>
  <link name="arm_5_link">
    <collision>
      <geometry>
        <cylinder radius="0.015" length="0.8"/>
      </geometry>
      <origin xyz="0.3939231012048832 0.0 0.06945927106677217" rpy="0.0 1.3962634015954636 0.0"/>
    </collision>
    <visual>
      <geometry>
        <cylinder radius="0.015" length="0.8"/>
      </geometry>
      <origin xyz="0.3939231012048832 0.0 0.06945927106677217" rpy="0.0 1.3962634015954636 0.0"/>
    </visual>
    <inertial>
      <mass value="0.05"/>
      <origin xyz="0.3939231012048832 0.0 0.06945927106677217" rpy="0.0 1.3962634015954636 0.0"/>
      <inertia ixx="0.0026694791666666672" ixy="0" ixz="0" iyy="0.0026694791666666672" iyz="0" izz="5.625e-06"/>
    </inertial>
  </link>
  <gazebo reference="arm_5_joint">
    <springStiffness>500</springStiffness>
    <springReference>0</springReference>
  </gazebo>
</robot>
